<?xml version="1.0"?>
<robot name="rosie_V1">
    <mobile type="mecanum" xyz="0.228 0 0" rpy="0 0 0" joints="right_wheel left_wheel"
            params="0.53 0.1"/> <!-- wheel_base, wheel_radius -->



  <material name="darkgrey">
    <color rgba="0.1 0.1 0.1 1.0"/>
  </material>
  <material name="grey">
    <color rgba="0.5 0.5 0.5 1.0"/>
  </material>
  <material name="blue">
    <color rgba="0.0 0.0 0.8 1.0"/>
  </material>
  <link name="base_footprint"/>

<link name="base_link">
<inertial>
    <mass value="3"/>
    <origin rpy="0 0 0" xyz="0 0 0"/>
    <inertia ixx="0.008906" ixy="0.0" ixz="0.0" iyy="0.021987" iyz="0.0" izz="0.027531"/>
</inertial>

    <visual>
      <origin rpy="0 0 0" xyz="0 0 0"/>
      <geometry>
        <box size="0.285 0.17 0.082"/>
      </geometry>
      <material name="grey"/>
    </visual>
    <collision>
      <origin rpy="0 0 0" xyz="0 0 0"/>
      <geometry>
        <box size="0.285 0.17 0.082"/>
      </geometry>
    </collision>

  </link>

  <link name="fl_wheel_link">
    <visual>
          <origin rpy="0 0 0" xyz="-0.013 0 0"/>

      <origin rpy="0 0 0" xyz="0 0 0"/>
      <geometry>
       <mesh filename="package://rosie_description/urdf/meshes/fl_wheel_link.STL"  scale="0.81 0.81 0.81"/>
      </geometry>
      <material name="darkgrey"/>
    </visual>
    <collision>
      <origin rpy="0 0 0" xyz="0 0 0"/>
      <geometry>
        <box size="0.058 0.082 0.082"/>
      </geometry>
    </collision>
    <inertial>
      <origin rpy="0 0 0" xyz="0 0 0"/>
      <mass value="0.5"/>
      <inertia ixx="0.00015" ixy="0" ixz="0" iyy="0.00015" iyz="0" izz="0.000225"/>
    </inertial>
  </link>

  <link name="fr_wheel_link">
    <visual>
      <origin rpy="0 0 0" xyz="-0.013 0 0"/>
      <geometry>
       <mesh filename="package://rosie_description/urdf/meshes/fr_wheel_link.STL"  scale="0.81 0.81 0.81"/>
      </geometry>
      <material name="darkgrey"/>
    </visual>
    <collision>
      <origin rpy="0 0 0" xyz="0 0 0"/>
      <geometry>
        <box size="0.058 0.082 0.082"/>
      </geometry>
    </collision>
    <inertial>
      <origin rpy="0 0 0" xyz="0 0 0"/>
      <mass value="0.5"/>
      <inertia ixx="0.00015" ixy="0" ixz="0" iyy="0.00015" iyz="0" izz="0.000225"/>
    </inertial>
  </link>

 <link name="rl_wheel_link">
    <visual>
      <origin rpy="0 0 0" xyz="-0.013 0 0"/>
      <geometry>
       <mesh filename="package://rosie_description/urdf/meshes/rl_wheel_link.STL"  scale="0.81 0.81 0.81"/>
      </geometry>
      <material name="darkgrey"/>
    </visual>
    <collision>
      <origin rpy="0 0 0" xyz="0 0 0"/>
      <geometry>
        <box size="0.058 0.082 0.082"/>
      </geometry>
    </collision>
    <inertial>
      <origin rpy="0 0 0" xyz="0 0 0"/>
      <mass value="0.5"/>
      <inertia ixx="0.00015" ixy="0" ixz="0" iyy="0.00015" iyz="0" izz="0.000225"/>
    </inertial>
  </link>

  <link name="rr_wheel_link">
    <visual>
      <origin rpy="0 0 0" xyz="-0.013 0 0"/>
      <geometry>
       <mesh filename="package://rosie_description/urdf/meshes/rr_wheel_link.STL"  scale="0.81 0.81 0.81"/>
      </geometry>
      <material name="darkgrey"/>
    </visual>
    <collision>
      <origin rpy="0 0 0" xyz="0 0 0"/>
      <geometry>
        <box size="0.058 0.082 0.082"/>
      </geometry>
    </collision>
    <inertial>
      <origin rpy="0 0 0" xyz="0 0 0"/>
      <mass value="0.5"/>
      <inertia ixx="0.00015" ixy="0" ixz="0" iyy="0.00015" iyz="0" izz="0.000225"/>
    </inertial>
  </link>
  <!-- Housing Link -->
  <link name="housing">
  <inertial>
    <mass value="3"/>
    <origin rpy="0.0 0.0 0.0" xyz="0.0 0.0 0.0"/>
    <inertia ixx="0.013625" ixy="0.0" ixz="0.0" iyy="0.02670625" iyz="0.0" izz="0.02753125"/>
</inertial>

    <visual>
      <geometry>
        <box size="0.285 0.17 0.16"/> <!-- Dimensions of the housing -->
      </geometry>
      <material name="rblue">
        <color rgba="0 1 0 1"/> <!-- Gray color -->
      </material>
    </visual>
    <collision>
      <geometry>
        <box size="0.285 0.17 0.16"/>
      </geometry>
    </collision>

  </link>

  <!-- Torso Link -->
  <link name="link_torso_5">
  <inertial>
    <mass value="5"/>
    <origin rpy="0.0 0.0 0.0" xyz="0.0 0.0 0.0"/>
    <inertia ixx="0.11834" ixy="0.0" ixz="0.0" iyy="0.11834" iyz="0.0" izz="0.025"/>
</inertial>

    <visual>
      <origin rpy="0 0 0" xyz="0 0 0.056"/>

      <geometry>
        <mesh filename="package://rosie_description/urdf/meshes/torso_link.stl"/>
      </geometry>
    </visual>
     <collision>
      <geometry>
<cylinder radius="0.1" length="0.504"/>
      </geometry>
    </collision>

  </link>

    <link name="link_right_arm_0">
    <inertial>
        <mass value="1.26"/>
        <origin xyz="0 0 0" rpy="1.5708 0 0"/>
        <inertia ixx="0.003183" ixy="0.0" ixz="0.0" iyy="0.001975" iyz="0.0" izz="0.003183"/>
    </inertial>

        <visual>

            <geometry>
                 <mesh filename="package://rosie_description/urdf/meshes/right_arm_0.stl"/>
            </geometry>
        </visual>

        <collision>
            <origin xyz="0 0 0" rpy="1.5708 0 0"/>
            <geometry>
                <cylinder radius="0.006" length="0.05"/>
            </geometry>
        </collision>
    </link>

    <link name="link_right_arm_1">
    <inertial>
        <mass value="2.2"/>
        <origin rpy="0.0 0.0 0.0" xyz="0.000 0.00 -0.1"/>
        <inertia ixx="0.06349" ixy="0.0" ixz="0.0" iyy="0.06349" iyz="0.0" izz="0.00814"/>
    </inertial>


        <visual>
           <origin rpy="0.0 0.0 0.0" xyz="0.000 0.00 -0.074"/>

            <geometry>
                 <mesh filename="package://rosie_description/urdf/meshes/right_arm_1.stl"/>
            </geometry>
        </visual>

        <collision>
                   <origin rpy="0.0 0.0 0.0" xyz="0.000 0.00 -0.1"/>

            <geometry>
                <cylinder radius="0.016" length="0.098" coltype="32"/>
                <!-- <cylinder sp="0.0 0.0 0.0" ep="0.0 0.0 -0.200" radius="0.050"/> -->
            </geometry>
        </collision>
    </link>

    <link name="link_right_arm_2">
    <inertial>
        <mass value="1.3"/>
        <origin rpy="0.0 0.0 0.0" xyz="0.000 0.00 -0.074"/>
        <inertia ixx="0.0035" ixy="0.0" ixz="0.0" iyy="0.0035" iyz="0.0" izz="0.00275"/>
    </inertial>


        <visual>
                   <origin rpy="0.0 0.0 0.0" xyz="0.000 0.00 -0.074"/>


            <geometry>
                 <mesh filename="package://rosie_description/urdf/meshes/right_arm_2.stl"/>
            </geometry>
        </visual>

        <collision>
                   <origin rpy="0.0 0.0 0.0" xyz="0.000 0.00 -0.074"/>
            <geometry>
                <cylinder radius="0.005" length="0.010" coltype="64"/>
                <!-- <cylinder sp="0.026 -0.040 -0.276" ep="0.026 0.040 -0.276" radius="0.05"/> -->
            </geometry>
        </collision>
    </link>

    <link name="link_right_arm_3">
    <inertial>
        <mass value="1.2"/>
        <origin rpy="0.0 0.0 0.0" xyz="0.000 0.00 -0.074"/>
        <inertia ixx="0.0035437" ixy="0.0" ixz="0.0" iyy="0.0035437" iyz="0.0" izz="0.00096"/>
    </inertial>

        <visual>
                           <origin rpy="0.0 0.0 0.0" xyz="0.000 0.00 -0.074"/>

            <geometry>
                 <mesh filename="package://rosie_description/urdf/meshes/right_arm_3.stl"/>
            </geometry>
        </visual>

        <collision>
                   <origin rpy="0.0 0.0 0.0" xyz="0.000 0.00 -0.074"/>
            <geometry>
                <cylinder radius="0.002" length="0.0092" coltype="128" colaffinity="30"/>
                <!-- <cylinder sp="-0.031 0.0 -0.05" ep="-0.031 0.0 -0.165" radius="0.04"/> -->
            </geometry>
        </collision>
    </link>

    <link name="link_right_arm_4">
        <inertial>
            <mass value="0.42508710"/>
            <origin rpy="0 0 0" xyz="-0.00000011 -0.02696036 0.06182110"/>
            <inertia ixx="0.00082466" ixy="0.0" ixz="0.0" iyy="0.00075398" iyz="-0.00025338"
                     izz="0.00039794"/>
        </inertial>

        <visual>
                   <origin rpy="0.0 0.0 0.0" xyz="0.000 0.00 -0.074"/>


            <geometry>
                 <mesh filename="package://rosie_description/urdf/meshes/LINK_11.dae"/>
            </geometry>
        </visual>
        <collision>
            <origin xyz="0 -0.038 0.0175" rpy="0 0 0"/>
            <geometry>
                <cylinder radius="0.015" length="0.1" coltype="256" colaffinity="30"/>
            </geometry>
        </collision>
    </link>

    <link name="link_right_arm_5">
        <inertial>
            <mass value="1.59194395"/>
            <origin rpy="0 0 0" xyz="0.00318034 -0.00532264 -0.02809655"/>
            <inertia ixx="0.00256054" ixy="-0.00002344" ixz="-0.00001563" iyy="0.00257233"
                     iyz="0.00021608" izz="0.00156092"/>
        </inertial>

        <visual>
                   <origin rpy="0.0 0.0 0.0" xyz="0.000 0.00 -0.074"/>

            <geometry>
                 <mesh filename="package://rosie_description/urdf/meshes/LINK_12.dae"/>
            </geometry>
        </visual>
        <collision>
            <origin xyz="0 0 -0.1" rpy="0 0 0"/>
            <geometry>
                <cylinder radius="0.006" length="0.0015" coltype="512" colaffinity="31"/>
                <!-- <cylinder sp="0.0 0.0 0.002" ep="0.0 0.0 -0.050" radius="0.075"/> -->
            </geometry>
        </collision>
    </link>

    <link name="link_right_arm_6">
        <inertial>
            <mass value="0.21137279"/>
            <origin rpy="0 0 0" xyz="0.00066810 -0.00031708 -0.09636043"/>
            <inertia ixx="0.00013511" ixy="-0.00000242" ixz="-0.00000102" iyy="0.00014453"
                     iyz="0.00000094" izz="0.00025431"/>
        </inertial>

        <visual>
                           <origin rpy="0.0 0.0 0.0" xyz="0.000 0.00 -0.074"/>

            <geometry>
                 <mesh filename="package://rosie_description/urdf/meshes/LINK_13.dae"/>
            </geometry>
        </visual>
                <collision>
            <origin xyz="0 0 -0.074" rpy="0 0 0"/>
            <geometry>
                <cylinder radius="0.006" length="0.01" coltype="512" colaffinity="31"/>
                <!-- <cylinder sp="0.0 0.0 0.002" ep="0.0 0.0 -0.050" radius="0.075"/> -->
            </geometry>
        </collision>
    </link>

    <link name="link_left_arm_0">
    <inertial>
        <mass value="1.26"/>
        <origin xyz="0 0 0" rpy="1.5708 0 0"/>
        <inertia ixx="0.003183" ixy="0.0" ixz="0.0" iyy="0.001975" iyz="0.0" izz="0.003183"/>
    </inertial>

        <visual>
            <geometry>
                 <mesh filename="package://rosie_description/urdf/meshes/left_arm_0.stl"/>
            </geometry>
        </visual>

 <collision>
            <origin xyz="0 0 0" rpy="1.5708 0 0"/>
            <geometry>
                <cylinder radius="0.056" length="0.065"/>
            </geometry>
        </collision>
    </link>

    <link name="link_left_arm_1">
    <inertial>
        <mass value="2.2"/>
        <origin rpy="0.0 0.0 0.0" xyz="0.000 0.00 -0.1"/>
        <inertia ixx="0.06349" ixy="0.0" ixz="0.0" iyy="0.06349" iyz="0.0" izz="0.00814"/>
    </inertial>

        <visual>
                   <origin rpy="0.0 0.0 0.0" xyz="0.000 0.00 -0.074"/>

            <geometry>
                 <mesh filename="package://rosie_description/urdf/meshes/left_arm_1.stl"/>
            </geometry>
        </visual>

        <collision>
                   <origin rpy="0.0 0.0 0.0" xyz="0.000 0.00 -0.1"/>

            <geometry>
                <cylinder radius="0.086" length="0.298" coltype="32"/>
                <!-- <cylinder sp="0.0 0.0 0.0" ep="0.0 0.0 -0.200" radius="0.050"/> -->
            </geometry>
        </collision>
    </link>

    <link name="link_left_arm_2">
    <inertial>
        <mass value="1.3"/>
        <origin rpy="0.0 0.0 0.0" xyz="0.000 0.00 -0.074"/>
        <inertia ixx="0.0035" ixy="0.0" ixz="0.0" iyy="0.0035" iyz="0.0" izz="0.00275"/>
    </inertial>

        <visual>
                   <origin rpy="0.0 0.0 0.0" xyz="0.000 0.00 -0.074"/>

            <geometry>
                 <mesh filename="package://rosie_description/urdf/meshes/left_arm_2.stl"/>
            </geometry>
        </visual>

        <collision>
                   <origin rpy="0.0 0.0 0.0" xyz="0.000 0.00 -0.074"/>
            <geometry>
                <cylinder radius="0.065" length="0.14" coltype="64"/>
                <!-- <cylinder sp="0.026 -0.040 -0.276" ep="0.026 0.040 -0.276" radius="0.05"/> -->
            </geometry>
        </collision>
    </link>

    <link name="link_left_arm_3">
    <inertial>
        <mass value="1.2"/>
        <origin rpy="0.0 0.0 0.0" xyz="0.000 0.00 -0.074"/>
        <inertia ixx="0.0035437" ixy="0.0" ixz="0.0" iyy="0.0035437" iyz="0.0" izz="0.00096"/>
    </inertial>

        <visual>
                   <origin rpy="0.0 0.0 0.0" xyz="0.000 0.00 -0.074"/>

            <geometry>
                 <mesh filename="package://rosie_description/urdf/meshes/left_arm_3.stl"/>
            </geometry>
        </visual>

        <collision>
                   <origin rpy="0.0 0.0 0.0" xyz="0.000 0.00 -0.074"/>
            <geometry>
                <cylinder radius="0.04" length="0.0892" coltype="128" colaffinity="30"/>
                <!-- <cylinder sp="-0.031 0.0 -0.05" ep="-0.031 0.0 -0.165" radius="0.04"/> -->
            </geometry>
        </collision>
    </link>

    <link name="link_left_arm_4">
        <inertial>
            <mass value="0.42508710"/>
            <origin rpy="0 0 0" xyz="0.00000011 0.02696036 0.06182110"/>
            <inertia ixx="0.00082466" ixy="0.0" ixz="0.0" iyy="0.00075398" iyz="0.00025338"
                     izz="0.00039794"/>
        </inertial>

        <visual>
                   <origin rpy="0.0 0.0 0.0" xyz="0.000 0.00 -0.074"/>

            <geometry>
                 <mesh filename="package://rosie_description/urdf/meshes/LINK_18.dae"/>
            </geometry>
        </visual>

        <collision>
            <origin xyz="0 0.038000 0.017500" rpy="0 0 0"/>
            <geometry>
                <cylinder radius="0.038" length="0.135" colaffinity="1022"/>
            </geometry>
        </collision>
    </link>

    <link name="link_left_arm_5">
        <inertial>
            <mass value="1.44264795"/>
            <origin rpy="0 0 0" xyz="0.00340082 0.00576824 -0.02507309"/>
            <inertia ixx="0.00233577" ixy="0.00003048" ixz="-0.00001191" iyy="0.00232580"
                     iyz="-0.00019491" izz="0.00138375"/>
        </inertial>

        <visual>
                   <origin rpy="0.0 0.0 0.0" xyz="0.000 0.00 -0.074"/>

            <geometry>
                 <mesh filename="package://rosie_description/urdf/meshes/LINK_19.dae"/>
            </geometry>
        </visual>

        <collision>
            <origin xyz="0 0 -0.1" rpy="0 0 0"/>
            <geometry>
                <cylinder radius="0.066" length="0.115" colaffinity="1023"/>
            </geometry>
        </collision>
    </link>

    <link name="link_left_arm_6">
        <inertial>
            <mass value="0.21137279"/>
            <origin rpy="0 0 0" xyz="-0.00066810 0.00031708 -0.09636043"/>
            <inertia ixx="0.00013511" ixy="-0.00000242" ixz="0.00000102" iyy="0.00014453"
                     iyz="-0.00000094" izz="0.00025431"/>
        </inertial>

        <visual>
                   <origin rpy="0.0 0.0 0.0" xyz="0.000 0.00 -0.074"/>

            <geometry>
                 <mesh filename="package://rosie_description/urdf/meshes/LINK_20.dae"/>
            </geometry>
        </visual>
                        <collision>
            <origin xyz="0 0 -0.074" rpy="0 0 0"/>
            <geometry>
                <cylinder radius="0.066" length="0.19" coltype="512" colaffinity="31"/>
                <!-- <cylinder sp="0.0 0.0 0.002" ep="0.0 0.0 -0.050" radius="0.075"/> -->
            </geometry>
        </collision>
    </link>
    <link name="link_robot_head">
        <inertial>
            <mass value="0.8"/>
            <origin rpy="0 0 0" xyz="0.0 0.0 0.0"/>
            <inertia ixx="0.001" ixy="0.0" ixz="0.0" iyy="0.001" iyz="0.0" izz="0.001"/>
        </inertial>

        <visual>
            <geometry>
                 <mesh filename="package://rosie_description/urdf/meshes/head.stl"/>
            </geometry>
        </visual>

        <collision>
            <geometry>
                <box size="0.147 0.154 0.108"/>

            </geometry>
        </collision>
    </link>



    <!-- Joints -->

  <joint name="base_joint" type="fixed">
    <parent link="base_footprint"/>
    <child link="base_link"/>
    <origin rpy="0 0 0" xyz="0 0 0"/>
  </joint>

  <joint name="fl_wheel_joint" type="continuous">
    <parent link="base_link"/>
    <child link="fl_wheel_link"/>
    <origin rpy="0 0 -1.5707963267948966"  xyz="-0.1135 -0.114 0"/>
    <axis rpy="0 0 0" xyz="1 0 0"/>
  </joint>

  <joint name="fr_wheel_joint" type="continuous">
    <parent link="base_link"/>
    <child link="fr_wheel_link"/>
    <origin rpy="0 0 1.5707963267948966" xyz="-0.1135 0.114 0"/>
    <axis rpy="0 0 0" xyz="-1 0 0"/>
  </joint>

  <joint name="rl_wheel_joint" type="continuous">
    <parent link="base_link"/>
    <child link="rl_wheel_link"/>
    <origin rpy="0 0 -1.5707963267948966"  xyz="0.1135 -0.114 0"/>
    <axis rpy="0 0 0" xyz="1 0 0"/>
  </joint>

  <joint name="rr_wheel_joint" type="continuous">
    <parent link="base_link"/>
    <child link="rr_wheel_link"/>
    <origin rpy="0 0 1.5707963267948966" xyz="0.1135 0.114 0"/>
    <axis rpy="0 0 0" xyz="-1 0 0"/>
  </joint>


  <!-- Joint Between Base and Housing -->
  <joint name="housing_joint" type="fixed">
    <parent link="base_link"/>
    <child link="housing"/>
    <origin xyz="0 0 0.121" rpy="0 0 0"/> <!-- Adjust for height of the base -->
  </joint>

  <!-- Joint Between Housing and Torso -->
  <joint name="torso_5" type="revolute">
    <parent link="housing"/>
    <child link="link_torso_5"/>
    <origin xyz="0 0 0.332" rpy="0 0 -1.5708"/> <!-- Position adjusted for correct alignment -->
    <axis xyz="0 1 0"/>
        <!-- Nm, rad/s^2, rad/s, (min) rad, (max) rad -->
        <!-- 120Nm, 5rad/s^2, 180deg/s, -135deg, 135deg -->
        <limit effort="120.0"
               acceleration="5.0"
               velocity="3.141592654"
               lower="-3.35619449"
               upper="3.35619449"
        />
    </joint>

    <joint name="right_arm_0" type="revolute">
        <parent link="link_torso_5"/>
        <child link="link_right_arm_0"/>
           <origin rpy="0 0 0" xyz="0.0 -0.128 0.168"/>
        <axis xyz="0 1 0"/>
        <!-- Nm, rad/s^2, rad/s, (min) rad, (max) rad -->
        <!-- 70Nm, 10rad/s^2, 180deg/s, -180deg, 180deg -->
        <limit effort="70.0"
               acceleration="10.0"
               velocity="3.141592654"
               lower="-1.5708"
               upper="0.2967"
        />
    </joint>

    <joint name="right_arm_1" type="revolute">
        <parent link="link_right_arm_0"/>
        <child link="link_right_arm_1"/>
           <origin rpy="0.0 0.0 0.0" xyz="0.012 -0.09 -0.000003"/>
        <axis xyz="-1 0 0"/>
        <!-- Nm, rad/s^2, rad/s, (min) rad, (max) rad -->
        <!-- 70Nm, 10rad/s^2, 180deg/s, -180deg, 1deg -->
        <limit effort="70.0"
               acceleration="10.0"
               velocity="3.141592654"
               lower="0"
               upper="1.5708"
        />
    </joint>

    <joint name="right_arm_2" type="revolute">
        <parent link="link_right_arm_1"/>
        <child link="link_right_arm_2"/>
        <origin rpy="0.0 0.0 0" xyz="0.012 -0.01 -0.236481"/>
        <axis xyz="0 0 -1"/>
        <!-- Nm, rad/s^2, rad/s, (min) rad, (max) rad -->
        <!-- 70Nm, 10rad/s^2, 180deg/s, -180deg, 180deg -->
        <limit effort="70.0"
               acceleration="10.0"
               velocity="3.141592654"
               lower="-0.7854"
               upper="0.7854"
        />
    </joint>

    <joint name="right_arm_3" type="revolute">
        <parent link="link_right_arm_2"/>
        <child link="link_right_arm_3"/>
        <origin rpy="0.0 0.0 0.0" xyz="-0.024 0.00 -0.1073"/>
        <axis xyz="0 1 0"/>
        <!-- Nm, rad/s^2, rad/s, (min) rad, (max) rad -->
        <!-- 40Nm, 10rad/s^2, 180deg/s, -150deg, 1deg -->
        <limit effort="40.0"
               acceleration="10.0"
               velocity="3.141592654"
               lower="-2.5307"
               upper="0"
        />
    </joint>

    <joint name="right_arm_4" type="revolute">
        <parent link="link_right_arm_3"/>
        <child link="link_right_arm_4"/>
            <origin rpy="0 0 0" xyz="0.0 0.0 -0.131"/>
        <axis xyz="0 0 -1"/>
        <!-- Nm, rad/s^2, rad/s, (min) rad, (max) rad -->
        <!-- 10Nm, 10rad/s^2, 360deg/s, -180deg, 180deg -->
        <limit effort="10.0"
               acceleration="10.0"
               velocity="6.283185308"
               lower="-3.141592654"
               upper="0"
        />
    </joint>

    <joint name="right_arm_5" type="revolute">
        <parent link="link_right_arm_4"/>
        <child link="link_right_arm_5"/>
        <origin rpy="0.0 -1.5708 0.0" xyz="0.0 0.0 0.0"/>
        <axis xyz="0 1 0"/>
        <!-- Nm, rad/s^2, rad/s, (min) rad, (max) rad -->
        <!-- 10Nm, 10rad/s^2, 360deg/s, -90deg, 110deg -->
        <limit effort="10.0"
               acceleration="10.0"
               velocity="6.283185308"
               lower="0"
               upper="3.1416"
        />
    </joint>

    <joint name="right_arm_6" type="revolute">
        <parent link="link_right_arm_5"/>
        <child link="link_right_arm_6"/>
        <origin rpy="0.0 0.0 0.0" xyz="0.0 0.0 0.0"/>
        <axis xyz="0 0 1"/>
        <!-- Nm, rad/s^2, rad/s, (min) rad, (max) rad -->
        <!-- 8Nm, 10rad/s^2, 120deg/s, -160deg, 160deg -->
        <limit effort="8.0"
               acceleration="10.0"
               velocity="2.094395102"
               lower="-2.792526803"
               upper="2.792526803"
        />
    </joint>

    <joint name="left_arm_0" type="revolute">
        <parent link="link_torso_5"/>
        <child link="link_left_arm_0"/>
           <origin rpy="0 0 0" xyz="0.0 0.128 0.168"/>
        <axis xyz="0 -1 0"/>
        <!-- Nm, rad/s^2, rad/s, (min) rad, (max) rad -->
        <!-- 70Nm, 10rad/s^2, 180deg/s, -180deg, 180deg -->
        <limit effort="70.0"
               acceleration="10.0"
               velocity="3.141592654"
               lower="-0.2967"
               upper="1.5708"
        />
    </joint>

    <joint name="left_arm_1" type="revolute">
        <parent link="link_left_arm_0"/>
        <child link="link_left_arm_1"/>
           <origin rpy="0.0 0.0 0.0" xyz="0.012 0.09 -0.000003"/>
        <axis xyz="1 0 0"/>
        <!-- Nm, rad/s^2, rad/s, (min) rad, (max) rad -->
        <!-- 70Nm, 10rad/s^2, 180deg/s, -1deg, 180deg -->
        <limit effort="70.0"
               acceleration="10.0"
               velocity="3.141592654"
               lower="0"
               upper="1.5708" 
        />
    </joint>

    <joint name="left_arm_2" type="revolute">
        <parent link="link_left_arm_1"/>
        <child link="link_left_arm_2"/>
        <origin rpy="0.0 0.0 0" xyz="0.012 0.025 -0.236481"/>
        <axis xyz="0 0 1"/>
        <!-- Nm, rad/s^2, rad/s, (min) rad, (max) rad -->
        <!-- 70Nm, 10rad/s^2, 180deg/s, -180deg, 180deg -->
        <limit effort="70.0"
               acceleration="10.0"
               velocity="3.141592654"
               lower="-0.7854"
               upper="0.7854"
        />
    </joint>

    <joint name="left_arm_3" type="revolute">
        <parent link="link_left_arm_2"/>
        <child link="link_left_arm_3"/>
        <origin rpy="0.0 0.0 0.0" xyz="-0.024 -0.01 -0.1073"/>
        <axis xyz="0 -1 0"/>
        <!-- Nm, rad/s^2, rad/s, (min) rad, (max) rad -->
        <!-- 40Nm, 10rad/s^2, 180deg/s, -150deg, 1deg -->
        <limit effort="40.0"
               acceleration="10.0"
               velocity="3.141592654"
               lower="0"
               upper="2.5307"
        />
    </joint>

    <joint name="left_arm_4" type="revolute">
        <parent link="link_left_arm_3"/>
        <child link="link_left_arm_4"/>
            <origin rpy="0 0 0" xyz="0.0 0.0 -0.131"/>
        <axis xyz="0 0 1"/>
        <!-- Nm, rad/s^2, rad/s, (min) rad, (max) rad -->
        <!-- 10Nm, 10rad/s^2, 360deg/s, -180deg, 180deg -->
        <limit effort="10.0"
               acceleration="10.0"
               velocity="6.283185308"
               lower="0"
               upper="3.141592654"
        />
    </joint>

    <joint name="left_arm_5" type="revolute">
        <parent link="link_left_arm_4"/>
        <child link="link_left_arm_5"/>
        <origin rpy="0.0 -1.5708 0.0" xyz="0.0 0.0 0.0"/>
        <axis xyz="0 1 0"/>
        <!-- Nm, rad/s^2, rad/s, (min) rad, (max) rad -->
        <!-- 10Nm, 10rad/s^2, 360deg/s, -90deg, 110deg -->
        <limit effort="10.0"
               acceleration="10.0"
               velocity="6.283185308"
               lower="0"
               upper="3.1416"
        />
    </joint>

    <joint name="left_arm_6" type="revolute">
        <parent link="link_left_arm_5"/>
        <child link="link_left_arm_6"/>
        <origin rpy="0.0 0.0 0.0" xyz="0.0 0.0 0.0"/>
        <axis xyz="0 0 1"/>
        <!-- Nm, rad/s^2, rad/s, (min) rad, (max) rad -->
        <!-- 8Nm, 10rad/s^2, 120deg/s, -160deg, 160deg -->
        <limit effort="8.0"
               acceleration="10.0"
               velocity="2.094395102"
               lower="-2.792526803"
               upper="2.792526803"
        />
    </joint>

    <joint name="head_pan_joint" type="revolute">
    <parent link="link_torso_5"/>
    <child link="link_robot_head"/>
    <origin rpy="0 0 0" xyz="0.0 0.0 0.306"/>
    <axis xyz="0 1 0"/>
    <limit effort="50.0" velocity="2.0" lower="-1.57" upper="1.57"/>
        </joint>

  <link
    name="left_gripper_base_link">
    <inertial>
      <origin
        xyz="0.00021987 -2.3546E-10 0.030163"
        rpy="0 0 0" />
      <mass
        value="0.30915" />
      <inertia
        ixx="0.00028972"
        ixy="-5.7879E-10"
        ixz="-1.8543E-06"
        iyy="0.00030737"
        iyz="1.682E-12"
        izz="0.00019914" />
    </inertial>
    <visual>
      <origin
        xyz="0 0 0"
        rpy="0 0 0" />
      <geometry>
       <mesh filename="package://rosie_description/urdf/meshes/robotiq_85_base_link_fine.STL" />
      </geometry>
      <material
        name="">
        <color
          rgba="0.1 0.1 0.1 1" />
      </material>
    </visual>
    <collision>
      <origin
        xyz="0 0 0"
        rpy="0 0 0" />
      <geometry>
       <mesh filename="package://rosie_description/urdf/meshes/robotiq_85_base_link_fine.STL" />
      </geometry>
    </collision>
  </link>

      <joint name="left_gripper" type="fixed">
        <parent link="link_left_arm_6"/>
        <child link="left_gripper_base_link"/>
        <origin rpy="3.142 0.0 0.0" xyz="0.0 0.0 -0.17"/>
        <axis xyz="0 0 1"/>
    </joint>

  <link
    name="la_left_outer_knuckle">
    <inertial>
      <origin
        xyz="0.0178331863169983 3.68915177224286E-11 0.0021442477325704"
        rpy="0 0 0" />
      <mass
        value="0.00684838849434396" />
      <inertia
        ixx="2.66832029033166E-07"
        ixy="1.66142314639824E-15"
        ixz="1.45945633322873E-07"
        iyy="1.3889233257419E-06"
        iyz="2.82951161241588E-15"
        izz="1.26603336914415E-06" />
    </inertial>
    <visual>
      <origin
        xyz="0 0 0"
        rpy="0 0 0" />
      <geometry>
       <mesh filename="package://rosie_description/urdf/meshes/outer_knuckle_fine.STL" />
      </geometry>
      <material
        name="">
        <color
          rgba="0.1 0.1 0.1 1" />
      </material>
    </visual>
    <collision>
      <origin
        xyz="0 0 0"
        rpy="0 0 0" />
      <geometry>
       <mesh filename="package://rosie_description/urdf/meshes/outer_knuckle_coarse.STL" />
      </geometry>
    </collision>
  </link>
  <joint
    name="left_finger_joint"
    type="revolute">
    <origin
      xyz="0.0306011444260539 0 0.0627920162695395"
      rpy="0 0 0" />
    <parent
      link="left_gripper_base_link" />
    <child
      link="la_left_outer_knuckle" />
    <axis
      xyz="0 -1 0" />
    <limit
	  lower="0"
      upper="0.725"
      velocity="2.0"
      effort="1000" />
  </joint>
  <link
    name="la_left_outer_finger">
    <inertial>
      <origin
        xyz= "0.00131451599174296 2.88942057994543E-15 0.0215404163180413"
        rpy="0 0 0" />
      <mass
        value="0.0273093985570947" />
      <inertia
        ixx="8.51629628283022E-06"
        ixy="2.58174336207405E-19"
        ixz="3.83829504344079E-07"
        iyy="6.9133328065108E-06"
        iyz="-7.58589926143789E-19"
        izz="2.25006832221981E-06" />
    </inertial>
    <visual>
      <origin
        xyz="0 0 0"
        rpy="0 0 0" />
      <geometry>
       <mesh filename="package://rosie_description/urdf/meshes/outer_finger_fine.STL" />
      </geometry>
      <material
        name="">
        <color
          rgba="0.1 0.1 0.1 1" />
      </material>
    </visual>
    <collision>
      <origin
        xyz="0 0 0"
        rpy="0 0 0" />
      <geometry>
       <mesh filename="package://rosie_description/urdf/meshes/outer_finger_coarse.STL" />
      </geometry>
    </collision>
  </link>
  <joint
    name="la_left_outer_finger_joint"
    type="fixed">
    <origin
      xyz="0.0316910442266543 0 -0.00193396375724605"
      rpy="0 0 0" />
    <parent
      link="la_left_outer_knuckle" />
    <child
      link="la_left_outer_finger" />
    <axis
      xyz="0 -1 0" />
  </joint>
  <link
    name="la_left_inner_knuckle">
    <inertial>
      <origin
        xyz="0.017097546626628 -3.93808524389535E-10 0.0224918438201868"
        rpy="0 0 0" />
      <mass
        value="0.0110930853895903" />
      <inertia
        ixx="4.23392770691541E-06"
        ixy="5.748978936968E-15"
        ixz="1.78855677119788E-06"
        iyy="3.96548790524392E-06"
        iyz="1.05464666369669E-14"
        izz="3.24068002883007E-06" />
    </inertial>
    <visual>
      <origin
        xyz="0 0 0"
        rpy="0 0 0" />
      <geometry>
       <mesh filename="package://rosie_description/urdf/meshes/inner_knuckle_fine.STL" />
      </geometry>
      <material
        name="">
        <color
          rgba="0.1 0.1 0.1 1" />
      </material>
    </visual>
    <collision>
      <origin
        xyz="0 0 0"
        rpy="0 0 0" />
      <geometry>
       <mesh filename="package://rosie_description/urdf/meshes/inner_knuckle_coarse.STL" />
      </geometry>
    </collision>
  </link>
  <joint
    name="la_left_inner_knuckle_joint"
    type="revolute">
    <origin
      xyz="0.0127000000001501 0 0.0693074999999639"
      rpy="0 0 0" />
    <parent
      link="left_gripper_base_link" />
    <child
      link="la_left_inner_knuckle" />
    <axis
      xyz="0 -1 0" />
    <limit
      lower="0"
      upper="0.8757"
      velocity="2.0"
      effort="1000" />
    <mimic
      joint="left_finger_joint"
      multiplier="1"
      offset="0" />
  </joint>
  <link
    name="la_left_inner_finger">
    <inertial>
      <origin
        xyz="0.0060275613594574 -6.29183141465421E-15 0.00669925693133241"
        rpy="0 0 0" />
      <mass
        value="0.00724255346165745" />
      <inertia
        ixx="1.47824274053603E-06"
        ixy="-3.94884463570303E-19"
        ixz="-3.45268847648622E-07"
        iyy="1.70064480838395E-06"
        iyz="3.5059838910097E-19"
        izz="4.77151336838364E-07" />
    </inertial>
    <visual>
      <origin
        xyz="0 0 0"
        rpy="0 0 0" />
      <geometry>
       <mesh filename="package://rosie_description/urdf/meshes/inner_finger_fine.STL" />
      </geometry>
      <material
        name="">
        <color
          rgba="0.1 0.1 0.1 1" />
      </material>
    </visual>
    <collision>
      <origin
        xyz="0 0 0"
        rpy="0 0 0" />
      <geometry>
       <mesh filename="package://rosie_description/urdf/meshes/inner_finger_coarse.STL" />
      </geometry>
    </collision>
  </link>
  <joint
    name="la_left_inner_finger_joint"
    type="revolute">
    <origin
      xyz="0.034585310861294 0 0.0454970193817975"
      rpy="0 0 0" />
    <parent
      link="la_left_inner_knuckle" />
    <child
      link="la_left_inner_finger" />
    <axis
      xyz="0 -1 0" />
    <limit
      lower="0"
      upper="0.8757"
      velocity="2.0"
      effort="1000" />
    <mimic
      joint="left_finger_joint"
      multiplier="-1"
      offset="0" />
  </joint>
  <link
    name="la_right_inner_knuckle">
    <inertial>
      <origin
        xyz="0.0168606186773776 3.93808471820465E-10 0.0226699950793434"
        rpy="0 0 0" />
      <mass
        value="0.0110930853895903" />
      <inertia
        ixx="4.27134775939882E-06"
        ixy="-8.53568456728898E-15"
        ixz="1.77774229944246E-06"
        iyy="3.96548790524392E-06"
        iyz="-8.45108024914164E-15"
        izz="3.20325997634666E-06" />
    </inertial>
    <visual>
      <origin
        xyz="0 0 0"
        rpy="0 0 0" />
      <geometry>
       <mesh filename="package://rosie_description/urdf/meshes/inner_knuckle_fine.STL" />
      </geometry>
      <material
        name="">
        <color
          rgba="0.1 0.1 0.1 1" />
      </material>
    </visual>
    <collision>
      <origin
        xyz="0 0 0"
        rpy="0 0 0" />
      <geometry>
       <mesh filename="package://rosie_description/urdf/meshes/inner_knuckle_coarse.STL" />
      </geometry>
    </collision>
  </link>
  <joint
    name="la_right_inner_knuckle_joint"
    type="revolute">
    <origin
      xyz="-0.0126999999998499 0 0.0693075000000361"
      rpy="0 0 3.14159265358979" />
    <parent
      link="left_gripper_base_link" />
    <child
      link="la_right_inner_knuckle" />
    <axis
      xyz="0 1 0" />
    <limit
      lower="0"
      upper="0.8757"
      velocity="2.0"
      effort="1000" />
    <mimic
      joint="left_finger_joint"
      multiplier="-1"
      offset="0" />
  </joint>
  <link
    name="la_right_inner_finger">
    <inertial>
      <origin
        xyz="0.00602756228812038 -6.47284509480176E-15 0.00669925609578108"
        rpy="0 0 0" />
      <mass
        value="0.00724255346165744" />
      <inertia
        ixx="1.47824283625957E-06"
        ixy="-3.95952064019123E-19"
        ixz="-3.45268708875543E-07"
        iyy="1.70064480838394E-06"
        iyz="3.55286507960029E-19"
        izz="4.77151241114822E-07" />
    </inertial>
    <visual>
      <origin
        xyz="0 0 0"
        rpy="0 0 0" />
      <geometry>
       <mesh filename="package://rosie_description/urdf/meshes/inner_finger_fine.STL" />
      </geometry>
      <material
        name="">
        <color
          rgba="0.1 0.1 0.1 1" />
      </material>
    </visual>
    <collision>
      <origin
        xyz="0 0 0"
        rpy="0 0 0" />
      <geometry>
       <mesh filename="package://rosie_description/urdf/meshes/inner_finger_coarse.STL" />
      </geometry>
    </collision>
  </link>
  <joint
    name="la_right_inner_finger_joint"
    type="revolute">
    <origin
      xyz="0.0341060475457406 0 0.0458573878541688"
      rpy="0 0 0" />
    <parent
      link="la_right_inner_knuckle" />
    <child
      link="la_right_inner_finger" />
    <axis
      xyz="0 1 0" />
    <limit
      lower="0"
      upper="0.8757"
      velocity="2.0"
      effort="1000" />
    <mimic
      joint="left_finger_joint"
      multiplier="1"
      offset="0" />
  </joint>
  <link
    name="la_right_outer_knuckle">
    <inertial>
      <origin
        xyz="0.0178097074051638 3.60493211424024E-11 0.00233123458346721"
        rpy="0 0 0" />
      <mass
        value="0.00684838849401352" />
      <inertia
        ixx="2.70004361573169E-07"
        ixy="1.59579467624491E-15"
        ixz="1.56396493788199E-07"
        iyy="1.38892332558312E-06"
        iyz="2.82357800318817E-15"
        izz="1.26286103637978E-06" />
    </inertial>
    <visual>
      <origin
        xyz="0 0 0"
        rpy="0 0 0" />
      <geometry>
       <mesh filename="package://rosie_description/urdf/meshes/outer_knuckle_fine.STL" />
      </geometry>
      <material
        name="">
        <color
          rgba="0.1 0.1 0.1 1" />
      </material>
    </visual>
    <collision>
      <origin
        xyz="0 0 0"
        rpy="0 0 0" />
      <geometry>
       <mesh filename="package://rosie_description/urdf/meshes/outer_knuckle_coarse.STL" />
      </geometry>
    </collision>
  </link>
  <joint
    name="la_right_outer_knuckle_joint"
    type="revolute">
    <origin
      xyz="-0.0306011444258893 0 0.0627920162695395"
      rpy="0 0 3.14159265358979" />
    <parent
      link="left_gripper_base_link" />
    <child
      link="la_right_outer_knuckle" />
    <axis
      xyz="0 1 0" />
    <limit
      lower="0"
      upper="0.8757"
      velocity="2.0"
      effort="1000" />
    <mimic
      joint="left_finger_joint"
      multiplier="-1"
      offset="0" />
  </joint>
  <link
    name="la_right_outer_finger">
    <inertial>
      <origin
        xyz="0.00108844269639009 -2.611488350845E-15 0.0215530225245502"
        rpy="0 0 0" />
      <mass
        value="0.0273093985570947" />
      <inertia
        ixx="8.52366028592721E-06"
        ixy="3.41683380899422E-19"
        ixz="3.18003675694284E-07"
        iyy="6.91333280651081E-06"
        iyz="7.37726682706417E-19"
        izz="2.24270431912283E-06" />
    </inertial>
    <visual>
      <origin
        xyz="0 0 0"
        rpy="0 0 0" />
      <geometry>
       <mesh filename="package://rosie_description/urdf/meshes/outer_finger_fine.STL" />
      </geometry>
      <material
        name="">
        <color
          rgba="0.1 0.1 0.1 1" />
      </material>
    </visual>
    <collision>
      <origin
        xyz="0 0 0"
        rpy="0 0 0" />
      <geometry>
       <mesh filename="package://rosie_description/urdf/meshes/outer_finger_coarse.STL" />
      </geometry>
    </collision>
  </link>
  <joint
    name="la_right_outer_finger_joint"
    type="fixed">
    <origin
      xyz="0.0317095909367246 0 -0.0016013564954687"
      rpy="0 0 0" />
    <parent
      link="la_right_outer_knuckle" />
    <child
      link="la_right_outer_finger" />
    <axis
      xyz="0 1 0" />
  </joint>



  <link
    name="right_gripper_base_link">
    <inertial>
      <origin
        xyz="0.00021987 -2.3546E-10 0.030163"
        rpy="0 0 0" />
      <mass
        value="0.30915" />
      <inertia
        ixx="0.00028972"
        ixy="-5.7879E-10"
        ixz="-1.8543E-06"
        iyy="0.00030737"
        iyz="1.682E-12"
        izz="0.00019914" />
    </inertial>
    <visual>
      <origin
        xyz="0 0 0"
        rpy="0 0 0" />
      <geometry>
       <mesh filename="package://rosie_description/urdf/meshes/robotiq_85_base_link_fine.STL" />
      </geometry>
      <material
        name="">
        <color
          rgba="0.1 0.1 0.1 1" />
      </material>
    </visual>
    <collision>
      <origin
        xyz="0 0 0"
        rpy="0 0 0" />
      <geometry>
       <mesh filename="package://rosie_description/urdf/meshes/robotiq_85_base_link_fine.STL" />
      </geometry>
    </collision>
  </link>

      <joint name="right_gripper" type="fixed">
        <parent link="link_right_arm_6"/>
        <child link="right_gripper_base_link"/>
        <origin rpy="3.142 0.0 0.0" xyz="0.0 0.0 -0.17"/>
        <axis xyz="0 0 1"/>
    </joint>

  <link
    name="ra_left_outer_knuckle">
    <inertial>
      <origin
        xyz="0.0178331863169983 3.68915177224286E-11 0.0021442477325704"
        rpy="0 0 0" />
      <mass
        value="0.00684838849434396" />
      <inertia
        ixx="2.66832029033166E-07"
        ixy="1.66142314639824E-15"
        ixz="1.45945633322873E-07"
        iyy="1.3889233257419E-06"
        iyz="2.82951161241588E-15"
        izz="1.26603336914415E-06" />
    </inertial>
    <visual>
      <origin
        xyz="0 0 0"
        rpy="0 0 0" />
      <geometry>
       <mesh filename="package://rosie_description/urdf/meshes/outer_knuckle_fine.STL" />
      </geometry>
      <material
        name="">
        <color
          rgba="0.1 0.1 0.1 1" />
      </material>
    </visual>
    <collision>
      <origin
        xyz="0 0 0"
        rpy="0 0 0" />
      <geometry>
       <mesh filename="package://rosie_description/urdf/meshes/outer_knuckle_coarse.STL" />
      </geometry>
    </collision>
  </link>
  <joint
    name="right_finger_joint"
    type="revolute">
    <origin
      xyz="0.0306011444260539 0 0.0627920162695395"
      rpy="0 0 0" />
    <parent
      link="right_gripper_base_link" />
    <child
      link="ra_left_outer_knuckle" />
    <axis
      xyz="0 -1 0" />
    <limit
	  lower="0"
      upper="0.725"
      velocity="2.0"
      effort="1000" />
  </joint>
  <link
    name="ra_left_outer_finger">
    <inertial>
      <origin
        xyz= "0.00131451599174296 2.88942057994543E-15 0.0215404163180413"
        rpy="0 0 0" />
      <mass
        value="0.0273093985570947" />
      <inertia
        ixx="8.51629628283022E-06"
        ixy="2.58174336207405E-19"
        ixz="3.83829504344079E-07"
        iyy="6.9133328065108E-06"
        iyz="-7.58589926143789E-19"
        izz="2.25006832221981E-06" />
    </inertial>
    <visual>
      <origin
        xyz="0 0 0"
        rpy="0 0 0" />
      <geometry>
       <mesh filename="package://rosie_description/urdf/meshes/outer_finger_fine.STL" />
      </geometry>
      <material
        name="">
        <color
          rgba="0.1 0.1 0.1 1" />
      </material>
    </visual>
    <collision>
      <origin
        xyz="0 0 0"
        rpy="0 0 0" />
      <geometry>
       <mesh filename="package://rosie_description/urdf/meshes/outer_finger_coarse.STL" />
      </geometry>
    </collision>
  </link>
  <joint
    name="ra_left_outer_finger_joint"
    type="fixed">
    <origin
      xyz="0.0316910442266543 0 -0.00193396375724605"
      rpy="0 0 0" />
    <parent
      link="ra_left_outer_knuckle" />
    <child
      link="ra_left_outer_finger" />
    <axis
      xyz="0 -1 0" />
  </joint>
  <link
    name="ra_left_inner_knuckle">
    <inertial>
      <origin
        xyz="0.017097546626628 -3.93808524389535E-10 0.0224918438201868"
        rpy="0 0 0" />
      <mass
        value="0.0110930853895903" />
      <inertia
        ixx="4.23392770691541E-06"
        ixy="5.748978936968E-15"
        ixz="1.78855677119788E-06"
        iyy="3.96548790524392E-06"
        iyz="1.05464666369669E-14"
        izz="3.24068002883007E-06" />
    </inertial>
    <visual>
      <origin
        xyz="0 0 0"
        rpy="0 0 0" />
      <geometry>
       <mesh filename="package://rosie_description/urdf/meshes/inner_knuckle_fine.STL" />
      </geometry>
      <material
        name="">
        <color
          rgba="0.1 0.1 0.1 1" />
      </material>
    </visual>
    <collision>
      <origin
        xyz="0 0 0"
        rpy="0 0 0" />
      <geometry>
       <mesh filename="package://rosie_description/urdf/meshes/inner_knuckle_coarse.STL" />
      </geometry>
    </collision>
  </link>
  <joint
    name="ra_left_inner_knuckle_joint"
    type="revolute">
    <origin
      xyz="0.0127000000001501 0 0.0693074999999639"
      rpy="0 0 0" />
    <parent
      link="right_gripper_base_link" />
    <child
      link="ra_left_inner_knuckle" />
    <axis
      xyz="0 -1 0" />
    <limit
      lower="0"
      upper="0.8757"
      velocity="2.0"
      effort="1000" />
    <mimic
      joint="right_finger_joint"
      multiplier="1"
      offset="0" />
  </joint>
  <link
    name="ra_left_inner_finger">
    <inertial>
      <origin
        xyz="0.0060275613594574 -6.29183141465421E-15 0.00669925693133241"
        rpy="0 0 0" />
      <mass
        value="0.00724255346165745" />
      <inertia
        ixx="1.47824274053603E-06"
        ixy="-3.94884463570303E-19"
        ixz="-3.45268847648622E-07"
        iyy="1.70064480838395E-06"
        iyz="3.5059838910097E-19"
        izz="4.77151336838364E-07" />
    </inertial>
    <visual>
      <origin
        xyz="0 0 0"
        rpy="0 0 0" />
      <geometry>
       <mesh filename="package://rosie_description/urdf/meshes/inner_finger_fine.STL" />
      </geometry>
      <material
        name="">
        <color
          rgba="0.1 0.1 0.1 1" />
      </material>
    </visual>
    <collision>
      <origin
        xyz="0 0 0"
        rpy="0 0 0" />
      <geometry>
       <mesh filename="package://rosie_description/urdf/meshes/inner_finger_coarse.STL" />
      </geometry>
    </collision>
  </link>
  <joint
    name="ra_left_inner_finger_joint"
    type="revolute">
    <origin
      xyz="0.034585310861294 0 0.0454970193817975"
      rpy="0 0 0" />
    <parent
      link="ra_left_inner_knuckle" />
    <child
      link="ra_left_inner_finger" />
    <axis
      xyz="0 -1 0" />
    <limit
      lower="0"
      upper="0.8757"
      velocity="2.0"
      effort="1000" />
    <mimic
      joint="right_finger_joint"
      multiplier="-1"
      offset="0" />
  </joint>
  <link
    name="ra_right_inner_knuckle">
    <inertial>
      <origin
        xyz="0.0168606186773776 3.93808471820465E-10 0.0226699950793434"
        rpy="0 0 0" />
      <mass
        value="0.0110930853895903" />
      <inertia
        ixx="4.27134775939882E-06"
        ixy="-8.53568456728898E-15"
        ixz="1.77774229944246E-06"
        iyy="3.96548790524392E-06"
        iyz="-8.45108024914164E-15"
        izz="3.20325997634666E-06" />
    </inertial>
    <visual>
      <origin
        xyz="0 0 0"
        rpy="0 0 0" />
      <geometry>
       <mesh filename="package://rosie_description/urdf/meshes/inner_knuckle_fine.STL" />
      </geometry>
      <material
        name="">
        <color
          rgba="0.1 0.1 0.1 1" />
      </material>
    </visual>
    <collision>
      <origin
        xyz="0 0 0"
        rpy="0 0 0" />
      <geometry>
       <mesh filename="package://rosie_description/urdf/meshes/inner_knuckle_coarse.STL" />
      </geometry>
    </collision>
  </link>
  <joint
    name="ra_right_inner_knuckle_joint"
    type="revolute">
    <origin
      xyz="-0.0126999999998499 0 0.0693075000000361"
      rpy="0 0 3.14159265358979" />
    <parent
      link="right_gripper_base_link" />
    <child
      link="ra_right_inner_knuckle" />
    <axis
      xyz="0 1 0" />
    <limit
      lower="0"
      upper="0.8757"
      velocity="2.0"
      effort="1000" />
    <mimic
      joint="right_finger_joint"
      multiplier="-1"
      offset="0" />
  </joint>
  <link
    name="ra_right_inner_finger">
    <inertial>
      <origin
        xyz="0.00602756228812038 -6.47284509480176E-15 0.00669925609578108"
        rpy="0 0 0" />
      <mass
        value="0.00724255346165744" />
      <inertia
        ixx="1.47824283625957E-06"
        ixy="-3.95952064019123E-19"
        ixz="-3.45268708875543E-07"
        iyy="1.70064480838394E-06"
        iyz="3.55286507960029E-19"
        izz="4.77151241114822E-07" />
    </inertial>
    <visual>
      <origin
        xyz="0 0 0"
        rpy="0 0 0" />
      <geometry>
       <mesh filename="package://rosie_description/urdf/meshes/inner_finger_fine.STL" />
      </geometry>
      <material
        name="">
        <color
          rgba="0.1 0.1 0.1 1" />
      </material>
    </visual>
    <collision>
      <origin
        xyz="0 0 0"
        rpy="0 0 0" />
      <geometry>
       <mesh filename="package://rosie_description/urdf/meshes/inner_finger_coarse.STL" />
      </geometry>
    </collision>
  </link>
  <joint
    name="ra_right_inner_finger_joint"
    type="revolute">
    <origin
      xyz="0.0341060475457406 0 0.0458573878541688"
      rpy="0 0 0" />
    <parent
      link="ra_right_inner_knuckle" />
    <child
      link="ra_right_inner_finger" />
    <axis
      xyz="0 1 0" />
    <limit
      lower="0"
      upper="0.8757"
      velocity="2.0"
      effort="1000" />
    <mimic
      joint="right_finger_joint"
      multiplier="1"
      offset="0" />
  </joint>
  <link
    name="ra_right_outer_knuckle">
    <inertial>
      <origin
        xyz="0.0178097074051638 3.60493211424024E-11 0.00233123458346721"
        rpy="0 0 0" />
      <mass
        value="0.00684838849401352" />
      <inertia
        ixx="2.70004361573169E-07"
        ixy="1.59579467624491E-15"
        ixz="1.56396493788199E-07"
        iyy="1.38892332558312E-06"
        iyz="2.82357800318817E-15"
        izz="1.26286103637978E-06" />
    </inertial>
    <visual>
      <origin
        xyz="0 0 0"
        rpy="0 0 0" />
      <geometry>
       <mesh filename="package://rosie_description/urdf/meshes/outer_knuckle_fine.STL" />
      </geometry>
      <material
        name="">
        <color
          rgba="0.1 0.1 0.1 1" />
      </material>
    </visual>
    <collision>
      <origin
        xyz="0 0 0"
        rpy="0 0 0" />
      <geometry>
       <mesh filename="package://rosie_description/urdf/meshes/outer_knuckle_coarse.STL" />
      </geometry>
    </collision>
  </link>
  <joint
    name="ra_right_outer_knuckle_joint"
    type="revolute">
    <origin
      xyz="-0.0306011444258893 0 0.0627920162695395"
      rpy="0 0 3.14159265358979" />
    <parent
      link="right_gripper_base_link" />
    <child
      link="ra_right_outer_knuckle" />
    <axis
      xyz="0 1 0" />
    <limit
      lower="0"
      upper="0.8757"
      velocity="2.0"
      effort="1000" />
    <mimic
      joint="right_finger_joint"
      multiplier="-1"
      offset="0" />
  </joint>
  <link
    name="ra_right_outer_finger">
    <inertial>
      <origin
        xyz="0.00108844269639009 -2.611488350845E-15 0.0215530225245502"
        rpy="0 0 0" />
      <mass
        value="0.0273093985570947" />
      <inertia
        ixx="8.52366028592721E-06"
        ixy="3.41683380899422E-19"
        ixz="3.18003675694284E-07"
        iyy="6.91333280651081E-06"
        iyz="7.37726682706417E-19"
        izz="2.24270431912283E-06" />
    </inertial>
    <visual>
      <origin
        xyz="0 0 0"
        rpy="0 0 0" />
      <geometry>
       <mesh filename="package://rosie_description/urdf/meshes/outer_finger_fine.STL" />
      </geometry>
      <material
        name="">
        <color
          rgba="0.1 0.1 0.1 1" />
      </material>
    </visual>
    <collision>
      <origin
        xyz="0 0 0"
        rpy="0 0 0" />
      <geometry>
       <mesh filename="package://rosie_description/urdf/meshes/outer_finger_coarse.STL" />
      </geometry>
    </collision>
  </link>
  <joint
    name="ra_right_outer_finger_joint"
    type="fixed">
    <origin
      xyz="0.0317095909367246 0 -0.0016013564954687"
      rpy="0 0 0" />
    <parent
      link="ra_right_outer_knuckle" />
    <child
      link="ra_right_outer_finger" />
    <axis
      xyz="0 1 0" />
  </joint>

</robot>
